2025-01-10 04:24:49,852 - INFO - Starting training pipeline
2025-01-10 04:24:49,852 - INFO - Using device: cpu
2025-01-10 04:24:49,852 - INFO - Loading data...
2025-01-10 04:24:52,349 - INFO - Data loaded and cleaned. Shape: (603, 4351)
2025-01-10 04:24:52,523 - INFO - Train set size: 482, Validation set size: 121
2025-01-10 04:25:10,170 - INFO - Data loaders created
2025-01-10 04:25:10,267 - INFO - Model initialized
2025-01-10 04:25:10,267 - INFO - Starting model training...
2025-01-10 04:25:14,303 - ERROR - Error during training: GranularityProcessor.forward() takes 2 positional arguments but 3 were given
Traceback (most recent call last):
  File "C:\Users\jegol\CryptoProjects\BOTGITREPO\CRYPTOBOTS\NNbot\TimeToPeak\models\time_to_peak_model.py", line 561, in main
    model, training_stats, best_val_loss = train_model(
  File "C:\Users\jegol\CryptoProjects\BOTGITREPO\CRYPTOBOTS\NNbot\TimeToPeak\models\time_to_peak_model.py", line 376, in train_model
    mean, log_var = model(batch)
  File "C:\Users\jegol\AppData\Local\Packages\PythonSoftwareFoundation.Python.3.10_qbz5n2kfra8p0\LocalCache\local-packages\Python310\site-packages\torch\nn\modules\module.py", line 1736, in _wrapped_call_impl
    return self._call_impl(*args, **kwargs)
  File "C:\Users\jegol\AppData\Local\Packages\PythonSoftwareFoundation.Python.3.10_qbz5n2kfra8p0\LocalCache\local-packages\Python310\site-packages\torch\nn\modules\module.py", line 1747, in _call_impl
    return forward_call(*args, **kwargs)
  File "C:\Users\jegol\CryptoProjects\BOTGITREPO\CRYPTOBOTS\NNbot\TimeToPeak\models\time_to_peak_model.py", line 240, in forward
    processed = self.granularity_processors[granularity](features, lengths)
  File "C:\Users\jegol\AppData\Local\Packages\PythonSoftwareFoundation.Python.3.10_qbz5n2kfra8p0\LocalCache\local-packages\Python310\site-packages\torch\nn\modules\module.py", line 1736, in _wrapped_call_impl
    return self._call_impl(*args, **kwargs)
  File "C:\Users\jegol\AppData\Local\Packages\PythonSoftwareFoundation.Python.3.10_qbz5n2kfra8p0\LocalCache\local-packages\Python310\site-packages\torch\nn\modules\module.py", line 1747, in _call_impl
    return forward_call(*args, **kwargs)
TypeError: GranularityProcessor.forward() takes 2 positional arguments but 3 were given
