2025-01-10 04:48:02,237 - INFO - Starting training pipeline
2025-01-10 04:48:02,237 - INFO - Using device: cpu
2025-01-10 04:48:02,237 - INFO - Loading data...
2025-01-10 04:48:04,657 - INFO - Data loaded and cleaned. Shape: (603, 4351)
2025-01-10 04:48:04,851 - INFO - Train set size: 482, Validation set size: 121
2025-01-10 04:48:24,254 - INFO - Data loaders created
2025-01-10 04:48:24,310 - INFO - Model initialized
2025-01-10 04:48:24,310 - INFO - Starting model training...
2025-01-10 04:48:28,770 - ERROR - Error during training: The shape of the mask [32, 32] at index 1 does not match the shape of the indexed tensor [32, 1] at index 1
Traceback (most recent call last):
  File "C:\Users\jegol\CryptoProjects\BOTGITREPO\CRYPTOBOTS\NNbot\TimeToPeak\models\time_to_peak_model.py", line 535, in main
    model, training_stats, best_val_loss = train_model(
  File "C:\Users\jegol\CryptoProjects\BOTGITREPO\CRYPTOBOTS\NNbot\TimeToPeak\models\time_to_peak_model.py", line 351, in train_model
    loss = criterion(mean, log_var, batch['targets'])
  File "C:\Users\jegol\AppData\Local\Packages\PythonSoftwareFoundation.Python.3.10_qbz5n2kfra8p0\LocalCache\local-packages\Python310\site-packages\torch\nn\modules\module.py", line 1736, in _wrapped_call_impl
    return self._call_impl(*args, **kwargs)
  File "C:\Users\jegol\AppData\Local\Packages\PythonSoftwareFoundation.Python.3.10_qbz5n2kfra8p0\LocalCache\local-packages\Python310\site-packages\torch\nn\modules\module.py", line 1747, in _call_impl
    return forward_call(*args, **kwargs)
  File "C:\Users\jegol\CryptoProjects\BOTGITREPO\CRYPTOBOTS\NNbot\TimeToPeak\utils\time_loss.py", line 37, in forward
    late_scale = 1.5 + 0.5 * torch.sigmoid(pred_error[late_mask] / target[late_mask])
IndexError: The shape of the mask [32, 32] at index 1 does not match the shape of the indexed tensor [32, 1] at index 1
